Crash report: 
Exception: 'dict' object is not callable
Traceback: 
  File "/Users/yesod/Desktop/Code/Arizona/alora/maestro/./MaestroCore/database.py", line 60, in main
    module.update_database(dbPath)
    ~~~~~~~~~~~~~~~~~~~~~~^^^^^^^^
  File "/Users/yesod/Desktop/Code/Arizona/alora/maestro/schedulerConfigs/Astrophotography/database_Astrophotography.py", line 64, in update_database
    candidateDf = Candidate.candidatesToDf(candidates)
  File "/Users/yesod/Desktop/Code/Arizona/alora/maestro/scheduleLib/candidateDatabase.py", line 217, in candidatesToDf
    candidateDicts = [candidate.asDict() for candidate in candidateList]
                      ~~~~~~~~~~~~~~~~^^
  File "/Users/yesod/Desktop/Code/Arizona/alora/maestro/scheduleLib/candidateDatabase.py", line 152, in asDict
    if key in self.__dict__():
              ~~~~~~~~~~~~~^^
